Workbook

Sheet Rates
A1: AFIMILK New Zealand - March 2026
A2: Territory: | B2: New Zealand
A3: Location: | B3: Auckland
A4: Units Of Measurement: | B4: kg / km
A5: Currency: | B5: NZD
A6: Segment | B6: Clause | C6: Category | D6: Unit Of Measure | E6: Rate | F6: QTY | G6: Total | H6: Details
A7: Inbound | B7: Per Order | C7: Regular | D7: Order | E7: 15.68 | F7: ='Scans Inbound '!L1-F12 -> 0 | G7: =F7*E7 -> 0 | H7: Scans Inbound' sheet
A8: Inbound | B8: Per Unit Scan | C8: Per Item | D8: Line | E8: 2.92 | F8: ='Scans Inbound '!Q2 -> 0 | G8: =F8*E8 -> 0 | H8: Scans Inbound' sheet
A9: Inbound | B9: Per Unit Scan | C9: Per Serial | D9: Serial | E9: 2.92 | F9: ='Scans Inbound '!S2 -> 0 | G9: =F9*E9 -> 0 | H9: Scans Inbound' sheet
A10: Inbound | B10: Per Unit Scan | C10: Per Box | D10: Box | E10: 2.92 | F10: ='Scans Inbound '!P2 -> 0 | G10: =F10*E10 -> 0 | H10: Scans Inbound' sheet
A11: Inbound | B11: Per Unit Scan | C11: Per Pallet | D11: Pallet | E11: 4.7 | F11: ='Scans Inbound '!R2 -> 0 | G11: =F11*E11 -> 0 | H11: Scans Inbound' sheet
A12: Return | B12: Per Order | C12: Regular | D12: Order | E12: 27.51 | F12: ='Scans Inbound '!N1 -> 0 | G12: =F12*E12 -> 0 | H12: Scans' sheet (previously RMA Processing fee)
A13: Return | B13: Per Unit Scan | C13: Per Item | D13: Line | E13: 2.92 | F13: ='Scans Inbound '!I26 -> 0 | G13: =F13*E13 -> 0 | H13: Scans Inbound' sheet
A14: Return | B14: Per Unit Scan | C14: Per Serial | D14: Serial | E14: 2.92 | F14: 0 | G14: =F14*E14 -> 0 | H14: Scans Inbound' sheet
A15: Return | B15: Per Unit Scan | C15: Per Box | D15: Box | E15: 2.92 | F15: ='Scans Inbound '!I28 -> 0 | G15: =F15*E15 -> 0 | H15: Scans Inbound' sheet
A16: Return | B16: Per Unit Scan | C16: Per Pallet | D16: Pallet | E16: 4.7 | F16: ='Scans Inbound '!I29 -> 0 | G16: =F16*E16 -> 0 | H16: Scans' sheet
A17: Outbound | B17: Per Order | C17: Domestic | D17: Order | E17: 15.68 | F17: ='Scans Outbound '!M2-F18-F19 -> 0 | G17: =F17*E17 -> 0 | H17: Scans Outbound' sheet
A18: Outbound | B18: Per Order | C18: International | D18: Order | E18: 15.68 | F18: 0 | G18: =F18*E18 -> 0 | H18: Scans Outbound' sheet
A19: Outbound | B19: Per Order | C19: Cross-Doc | D19: Order | E19: 33.02 | F19: 0 | G19: =F19*E19 -> 0 | H19: Scans Outbound' sheet
A20: Outbound | B20: Per Unit Scan | C20: Per Item | D20: Line | E20: 2.92 | F20: ='Scans Outbound '!R6 -> 0 | G20: =F20*E20 -> 0 | H20: Scans Outbound' sheet
A21: Outbound | B21: Per Unit Scan | C21: Per Serial | D21: Serial | E21: 2.92 | F21: ='Scans Outbound '!T6 -> 0 | G21: =F21*E21 -> 0 | H21: Scans Outbound' sheet
A22: Outbound | B22: Per Unit Scan | C22: Per Box | D22: Box | E22: 2.92 | F22: ='Scans Outbound '!Q6 -> 0 | G22: =F22*E22 -> 0 | H22: Scans Outbound' sheet
A23: Outbound | B23: Per Unit Scan | C23: Per Pallet | D23: Pallet | E23: 4.7 | F23: ='Scans Outbound '!S6 -> 0 | G23: =F23*E23 -> 0 | H23: Scans Outbound' sheet
A24: Outbound | B24: Per Unit Scan | C24: Exws Handling | D24: Surcharge Per Order | E24: 20.9 | F24: 0 | G24: =F24*E24 -> 0 | H24: Scans Outbound' sheet
A25: Storage | B25: Location | C25: Pallet | D25: Per Week | E25: 6.33 | F25: ='Storage '!I5 -> 0 | G25: =F25*E25 -> 0 | H25: Storage' sheet
A26: Storage | B26: Location | C26: Shelf | D26: Per Week | E26: 1.87 | F26: ='Storage '!J5 -> 0 | G26: =F26*E26 -> 0 | H26: Storage' sheet
A27: VAS | B27: MIR | C27: Exception Case | D27: Each | E27: 20.9 | F27: =VAS!F14 -> 0 | G27: =F27*E27 -> 0 | H27: VAS' sheet
A28: VAS | B28: Labour | C28: WH Labour Hours | D28: Per Hour | E28: 59 | F28: 0 | G28: =F28*E28 -> 0 | H28: VAS' sheet
A29: VAS | B29: Labour | C29: CS/Admin Labor Hours | D29: Per Hour | E29: 75 | F29: 0 | G29: =F29*E29 -> 0 | H29: VAS' sheet
A30: VAS | B30: Labour | C30: Technician | D30: Per H (Min 2h) | E30: 61.66 | F30: 0 | G30: =F30*E30 -> 0
A31: VAS | B31: Handling | C31: Materials | D31: Cost +% | E31: 0.15 | F31: 0 | G31: =F31*E31 -> 0
A32: VAS | B32: Handling | C32: Wrapping | D32: Pallet | E32: 6.27 | F32: 0 | G32: =F32*E32 -> 0
A33: VAS | B33: Handling | C33: Repacking, Sorting Or Restacking | D33: Case | E33: 2.09 | F33: =SUM('Scans Outbound '!G2:G19) -> 0 | G33: =F33*E33 -> 0 | H33: Scans' sheet
A34: Container | B34: Handling | C34: ATF Fee | D34: Per Container | E34: 135.85 | F34: 0 | G34: =F34*E34 -> 0
A35: Container | B35: Handling | C35: Container Devanning - Palletised | D35: Per 20' | E35: 355.3 | F35: 0 | G35: =F35*E35 -> 0
A36: Container | B36: Handling | C36: Container Devanning - Loose | D36: Per 20' | E36: 637.45 | F36: 0 | G36: =F36*E36 -> 0
A37: Container | B37: Handling | C37: Container Devanning - Palletised | D37: Per 40' | E37: 637.45 | F37: 0 | G37: =F37*E37 -> 0
A38: Container | B38: Handling | C38: Container Devanning - Loose | D38: Per 40' | E38: 919.6 | F38: 0 | G38: =F38*E38 -> 0
A39: Management | B39: Miscellaneous | C39: Manual Order Creation Or Editing | D39: Order | E39: 20.9 | F39: =VAS!C14 -> 0 | G39: =F39*E39 -> 0 | H39: VAS' sheet
A40: Management | B40: Miscellaneous | C40: Order Cancellation | D40: Order | E40: 15.68 | F40: =VAS!C20 -> 0 | G40: =F40*E40 -> 0
...

Sheet Storage 
A1: Name (Warehouses) | B1: Weeks | C1: Day of Created At (Stats) | D1: Locations of type Pallet | E1: Locations of type Shelf
A2: Rohlig NZ
I3: Locations of Pallet | J3: Locations of Shelf
H5: Total | I5: =D9+D17+D25+D33 -> 0 | J5: =E9+E17+E25+E33 -> 0
C9: Total
C17: Total
C25: Total
C33: Total
C41: Total

Sheet Scans Inbound 
A1: inbound | B1: Sub Inventory | C1: Name (Service Levels) | D1: Ref (Orders) | E1: Inbound at | F1: Item | G1: box | H1: item | I1: pallet | J1: serial | K1: Inbound orders total | L1: =COUNTA(D2:D646) -> 0 | M1: RMA Processing fee | N1: 0 | P1: Box | Q1: item | R1: Pallet | S1: serial
O2: inbound Total | P2: =SUM(G2:G310) -> 0 | Q2: =SUM(H2:H310) -> 0 | R2: =SUM(I2:I310) -> 0 | S2: =SUM(J2:J310) -> 0

Sheet Scans Outbound 
A1: Outbound | B1: Sub Inventory | C1: Name (Service Levels) | D1: Dom/Int'l | E1: Ref (Orders) | F1: Shipped out | G1: Repacking/Labeling | H1: box | I1: item | J1: pallet | K1: serial
L2: Outbound orders total | M2: =COUNTA(E2:E977)-M4 -> 0
L4: CD TOTAL | M4: 0
P5: Repacking/Labeling | Q5: box | R5: item | S5: pallet | T5: serial
O6: Outbound Total | P6: =SUM(G2:G25) -> 0 | Q6: =SUM(H2:H25) -> 0 | R6: =SUM(I2:I558) -> 0 | S6: =SUM(J2:J558) -> 0 | T6: =SUM(K2:K558) -> 0

Sheet Distribution outbound 
A1: Date | B1: Week Day | C1: Order Ref | D1: Track Refs | E1: charge_Rate | F1: Rate including fuel | G1: Total (Inc. GST)
L2: Total:
L3: =SUM(F2:F50) -> 0

Sheet VAS
A1: Manual Order Creation Or Editing | E1: Exception Case MIR Ref | I1: WH Labour Hours | M1: Ibnound Sorting fee (If required)
C14: =SUM(C2:C13) -> 0 | F14: =SUM(F2:F13) -> 0 | I14: =SUM(I2:I13) -> 0 | N14: =SUM(N2:N13) -> 0
A17: Order Cancellation
C20: =SUM(C18:C19) -> 0

Sheet Management
A1: Display Name | B1: Month of Created At (Orders) | C1: Name (Users) | D1: order_type | E1: Ref (Orders) | F1: Year of Created At (Orders) | G1: Distinct count of Ref (Orders)
A2: Afimilk New Zealand | B2: מרץ | C2: Tomer Lev Pell-Duev | D2: Manual Order | E2: OceanNZTOUSMAR012026 | F2: 2026 | G2: 1
A3: Afimilk New Zealand | B3: מרץ | C3: Tomer Lev Pell-Duev | D3: Manual Order | E3: RTVSO25NZ0454-220326 | F3: 2026 | G3: 1
A4: Afimilk New Zealand | B4: מרץ | C4: Tomer Lev Pell-Duev | D4: Manual Order | E4: SO26NZ0035-1 | F4: 2026 | G4: 1
A5: Afimilk New Zealand | B5: מרץ | C5: Tomer Lev Pell-Duev | D5: Manual Order | E5: SO26NZ0035-1Return | F5: 2026 | G5: 1
A6: Afimilk New Zealand | B6: מרץ | C6: Tomer Lev Pell-Duev | D6: Manual Order | E6: SO26NZ0036-1 | F6: 2026 | G6: 1
A7: Afimilk New Zealand | B7: מרץ | C7: Tomer Lev Pell-Duev | D7: Manual Order | E7: SO26NZ0036-1Return | F7: 2026 | G7: 1

Sheet Analyze
A1: Type | B1: Ref (Orders) | C1: Order count | D1: QTY
A2: Inbound
B3: Total | C3: 6 | D3: 0
A4: Outbound
B5: Total | C5: 12 | D5: 0
A6: Storage
B7: Total | C7: 74 | D7: 3389
A8: VAS
B9: Total | C9: 2 | D9: 0
A10: Management
B11: Total | C11: 6 | D11: 6
